Workbook

Sheet 19-20
C4: Statement of account since 02.12.2019 till 31st March 2020
C5: Income | F5: Expenditure | H5: Balance
C6: Date | D6: Received from | E6: Amount | F6: Purpose | G6: Amount | H6: Cash in hand
C7: 03.12.2019 | D7: K. C. Tripathi | E7: 1100 | H7: =E7 -> 1100
C8: 03.12.2019 | D8: Mrs. Neera Tripathi | E8: 1000 | H8: =H7+E8 -> 2100
C9: 03.12.2019 | D9: Atul Verma | E9: 500 | H9: =H8+E9 -> 2600
C10: 03.12.2019 | F10: Birth day of Development Car founder | G10: 1450 | H10: =H9+E10-G10 -> 1150
C11: 05.12.2019 | D11: Pranshu Tripathi | E11: 1500 | F11: Meetings with like mided people to establish an appropriate instute | G11: 900 | H11: =H10+E11-G11 -> 1750
C12: 23.12.2019 | F12: Meetings with memers of Self Help Group | G12: 1500 | H12: =H11+E12-G12 -> 250
C13: 25.12.2019 | D13: Mrs. Neera Tripathi | E13: 2000 | F13: Meetings with villagers to explore opportunity | G13: 2110 | H13: =H12+E13-G13 -> 140
C14: 13 .01.2020 | D14: K. C. Tripathi | E14: 2000 | F14: Meeting with villagers to slect local people to provide position in management of trust | G14: 890 | H14: =H13+E14-G14 -> 1250
C15: 14 .01.2020 | F15: Meeting to finalise objectives of trust and members of BoT | G15: 160 | H15: =H14+E15-G15 -> 1090
C16: 26 .01.2019 | D16: Pranshu Tripathi | E16: 2100 | F16: Participatory planning to develop village as live model on process of development | G16: 350 | H16: =H15+E16-G16 -> 2840
C17: 31.01.2020 | F17: Registration of Trust | G17: 2600 | H17: =H16+E17-G17 -> 240
C18: 02.02.2020 | D18: Neera Tripathu | E18: 1100 | F18: Planning KRANTI for Swaraj | G18: 170 | H18: =H17+E18-G18 -> 1170
C19: 08.03.2020 | F19: PAC card | G19: 250 | H19: =H18+E19-G19 -> 920
C20: 12.03.2020 | D20: Mrs. Neera Tripathi | E20: 500 | F20: Meeting with villagers on Transperancy and Devlopment | G20: 900 | H20: =H19+E20-G20 -> 520
C21: 30.03.2020 | F21: Review meeting | G21: 380 | H21: =H20+E21-G21 -> 140
C22: Total Income | E22: =SUM(E7:E21) -> 11800 | F22: Total expenditure | G22: =SUM(G10:G21) -> 11660

Sheet 20-21
B4: Statement of account since 1st April 2020 till 31st March 2021
B5: Date | C5: Received from | D5: Cash | E5: Through Bank | F5: Deposited in bank | G5: Withdrawn from bank | H5: Expenditure | J5: Balance
H6: Purpose | I6: Amount | J6: Cash in hand | K6: Cash in Bank
B7: 01.04.2020 | C7: BF | J7: 140
B8: 22.04.2020 | C8: K. C. Tripathi | D8: 1000 | H8: Earth Day | I8: 780 | J8: =J7+D8-I8 -> 360
B9: 05.05.2020 | C9: Pranshu Tripathi | D9: 500 | H9: Environment Day | I9: 210 | J9: =J8+D9-I9 -> 650
B10: 30.06.2020 | C10: Neera Tripathi (RD) | D10: 11000 | F10: 10000 | H10: A/C opening in SBI | I10: 10000 | J10: =J9+D10-I10 -> 1650 | K10: 10000
B11: 01.07.2020 | H11: Cheque book issue charges | I11: 177 | K11: =K10-I11 -> 9823
B12: 04.7.2020 | C12: K. C. Tripathi | D12: 1100 | F12: 1100 | K12: =K11+D12 -> 10923
B13: 25.09.2020 | H13: Birth day of Bank Uncle | I13: 240 | J13: =J10-I13 -> 1410 | K13: 10923
B14: 12.10.2020 | C14: BRP | E14: 120 | K14: =K13+E14-I14 -> 11043
B15: 13.10.2020 | C15: BRP | E15: 121 | K15: =K14+E15-I15 -> 11164
B16: 13.10.2020 | H16: Bank charges | I16: 10 | K16: =K15+E16-I16 -> 11154
B17: 15.10.2020 | C17: BRP | E17: 333 | K17: =K16+E17 -> 11487
B18: 05.11.2020 | C18: BRP | E18: 111 | K18: =K17+E18-I18 -> 11598
B19: 03.12.2020 | H19: Foundation day of AIRD | I19: 480 | J19: =J13-I19 -> 930 | K19: 11598
B20: 12.01.2021 | H20: Vivaknada Jayanti | I20: 470 | J20: =J19-I20 -> 460 | K20: 11598
B21: 12.03.2021 | H21: A/C keeping charges | I21: 454.93 | K21: =K18-I21 -> 11143.07
B22: Income Total | D22: =SUM(D8:D21) -> 13600 | E22: =SUM(E8:E21) -> 685 | H22: Total Expenditure | I22: =SUM(I8:I21) -> 12821.93
E26: =D22+E22 -> 14285

Sheet 21-22
C3: Statement of account since 1st April 2021 till 31st March 2022
C4: Date | D4: Received from | E4: Cash | F4: Through Bank | G4: Deposited in bank | H4: Withdrawan from bank | I4: Expenditure | K4: Balance
I5: Purpose | J5: Amount | K5: Cash in hand | L5: Cash in Bank
C6: B/F | K6: 460 | L6: ='20-21'!K21 -> 11143.07
C7: 20.09/21 | D7: K. C. Tripathi | E7: 1100 | K7: =K6+E7 -> 1560 | L7: 11143.07
C8: 25.09.21 | I8: Birthday of Bank uncle | J8: 660 | K8: =K7-J8 -> 900 | L8: 11143.07
C9: 22.12.21 | D9: Razor pay | F9: 1 | K9: 900 | L9: =L6+F9 -> 11144.07
C10: 29.12.21 | D10: Razor pay | F10: 1 | K10: 900 | L10: =L9+F10 -> 11145.07
C11: 03.01.22 | D11: Ankur (RD) | F11: 1000 | K11: 900 | L11: =L10+F11 -> 12145.07
C12: 04.01.22 | D12: Bhawana (RD) | F12: 1000 | K12: 900 | L12: =L11+F12 -> 13145.07
C13: o4.01.22 | D13: Neera Tripathi | E13: 2100 | K13: =K8+E13 -> 3000 | L13: 13145.07
C14: 12.01.22 | I14: Vivekananda Jayanti | J14: 1650 | K14: =K13-J14 -> 1350 | L14: 13145.07
C15: 17.01.22 | D15: K. C. Tripathi | E15: 1000 | G15: 1000 | K15: 1350 | L15: =L12+E15 -> 14145.07
C16: 17.01.22 | D16: Neera Tripathi (RD) | E16: 1000 | G16: 1000 | K16: 1350 | L16: =L15+E16 -> 15145.07
C17: 01.02.22 | D17: Razor pay | F17: 1 | K17: 1350 | L17: =L16+F17 -> 15146.07
C18: 17.02.22 | D18: Peanshu Tripathi (RD) | E18: 2000 | G18: 2000 | K18: 1350 | L18: =L17+E18 -> 17146.07
C19: 08.3.22 | D19: Razor pay | F19: 1 | K19: 1350 | L19: =L18+F19 -> 17147.07
C20: 08.03.22 | D20: Kutumbh | F20: 101 | K20: 1350 | L20: =L19+F20 -> 17248.07
C21: 08.03.22 | D21: Kutumbh | F21: 101 | K21: 1350 | L21: =L20+F21 -> 17349.07
C22: 11.03.22 | D22: Kutumbh | F22: 101 | K22: 1350 | L22: =L21+F22 -> 17450.07
C23: 12.03.22 | I23: A/C keeping charges | J23: 649 | K23: 1350 | L23: =L22-J23 -> 16801.07
C24: 17.03.22 | D24: Ravi | F24: 3990 | K24: 1350 | L24: =L23+F24 -> 20791.07
C25: 17.03.22 | D25: Kutumbh | F25: 101 | K25: 1350 | L25: =L24+F25 -> 20892.07
C26: 19.03.22 | D26: Kutumbh | F26: 101 | K26: 1350 | L26: =L25+F26 -> 20993.07
C27: 21.03.22 | F27: 501 | K27: 1350 | L27: =L26+F27 -> 21494.07
C28: 31.03.22 | H28: 5000 | I28: DR | J28: 5000 | K28: 1350 | L28: =L27-J28 -> 16494.07
C29: Total | E29: =SUM(E7:E28) -> 7200 | F29: =SUM(F7:F28) -> 7000 | G29: =SUM(G15:G28) -> 4000 | H29: =SUM(H7:H28) -> 5000 | I29: Total Expenditure | J29: =SUM(J8:J28) -> 7959

Sheet 22-23
C3: Statement of account period - 1st April 2022 till 31st March 2023
C4: Date | E4: Cash | F4: Through Bank | G4: Deposited in Bank | H4: Withdrawn from Bank | I4: Expenditure | K4: Balance
I5: Purpose | J5: Amount | K5: Cash in hand | L5: Cash in Bank
C6: B/F | K6: 1350 | L6: 16494.07
C7: 21.04.22 | D7: K. C. Tripathi | E7: 1000 | K7: =K6+E7-J7 -> 2350 | L7: =L6+F7+G7 -> 16494.07
C8: 22.04.22 | I8: Earth Day | J8: 890 | K8: =K7+E8-J8 -> 1460 | L8: =L7+F7+G7 -> 16494.07
C9: 18.05.22 | H9: 5000 | I9: Donation returned (RD) to repay loan of last financial year | J9: 5000 | K9: 1460 | L9: =L8+F8+G8-H9 -> 11494.07
C10: 13.07.22 | D10: Shriya | F10: 2700 | K10: 1460 | L10: =L9+F10+G10-H10 -> 14194.07
C11: 16.07.22 | D11: Neera Tripathi Returnable donation (RD) | E11: 11000 | G11: 11000 | K11: 1460 | L11: =L10+F11+G11-H11 -> 25194.07
C12: 16.07.23 | D12: Pranshu Tripathi (RD) | E12: 11000 | G12: 11000 | K12: 1460 | L12: =L11+F12+G12-H12 -> 36194.07
C13: 17.07.22 | D13: Atul Verma (RD) | E13: 7800 | G13: 7800 | I13: Meeting of Bord dorectors | J13: 880 | K13: 1460 | L13: =L12+F13+G13-H13 -> 43994.07
C14: 31.07.23 | D14: Pranshu Tripathi | E14: 500 | K14: =K13+E14-J14 -> 1960 | L14: =L13+F14+G14-H14 -> 43994.07
C15: 25.9.23 | D15: K.C. Tripathi | E15: 1000 | I15: Bank Uncle Day | J15: 1240 | K15: =K14+E15-J15 -> 1720 | L15: =L14+F15+G15-H15 -> 43994.07
C16: 14.11.22 | D16: Shriya | F16: 3296 | K16: 1720 | L16: =L15+F16+G16-H16 -> 47290.07
C17: 29.11.22 | D17: Rajiv | F17: 110 | K17: 1720 | L17: =L16+F17+G17-H17 -> 47400.07
C18: 01.12.22 | D18: Shriya | F18: 3000 | K18: 1720 | L18: =L17+F18+G18-H18 -> 50400.07
C19: 3.12.22 | I19: Development Car Day | J19: 870 | K19: =K18-J19 -> 850 | L19: =L18+F19+G19-H19 -> 50400.07
C20: 05.12.22 | D20: Rajiv | F20: 415 | K20: 850 | L20: =L19+F20+G20-H20 -> 50815.07
C21: 12.12.22 | H21: 11000 | I21: DR | J21: 11000 | K21: 850 | L21: =L20+F21+G21-H21 -> 39815.07
C22: 14.12.22 | D22: Rajiv | F22: 100 | K22: 850 | L22: =L21+F22+G22-H22 -> 39915.07
C23: 28.12.22 | H23: 11000 | I23: DR | J23: 11000 | K23: 850 | L23: =L22+F23+G23-H23 -> 28915.07
C24: 30.12.22 | D24: Neera Tripathi | E24: 3000 | K24: 3850 | L24: =L23+F24+G24-H24 -> 28915.07
C25: 12.01.23 | I25: Vivekananda Jayanti | J25: 1800 | K25: =K24-J25 -> 2050 | L25: =L24+F25+G25-H25 -> 28915.07
C26: 14.01.23 | I26: Spritual science and development | J26: 880 | K26: =K25-J26 -> 1170 | L26: =L25+F26+G26-H26 -> 28915.07
C27: 17.01.23 | I27: Website development | J27: 3000 | K27: 1170 | L27: =L26+F27+G27-H27-J27 -> 25915.07
C28: 27.01.23 | D28: Rajiv (RD) | F28: 4000 | K28: 1170 | L28: =L27+F28+G28-H28 -> 29915.07
C29: 27.01.23 | D29: Shriya | F29: 3160 | K29: 1170 | L29: =L28+F29+G29-H29 -> 33075.07
C30: 31/1/23 | I30: Foundation Day | J30: 760 | K30: =K29-J30 -> 410 | L30: =L29+F30+G30-H30 -> 33075.07
C31: 14.02.23 | H31: 17000 | K31: =K30+H31-J31 -> 17410 | L31: =L30+F31+G31-H31 -> 16075.07
C32: 16.02.23 | I32: Old laptop | J32: 12000 | K32: =K31+H32-J32 -> 5410 | L32: =L31+F32+G32-H32 -> 16075.07
C33: 18.02.23 | I33: Community dinner | J33: 1400 | K33: =K32+H33-J33 -> 4010 | L33: =L32+F33+G33-H33 -> 16075.07
C34: 22.02.23 | I34: Medical support to Archna | J34: 2600 | K34: =K33+H34-J34 -> 1410 | L34: =L33+F34+G34-H34 -> 16075.07
C35: 26.02.23 | I35: Community meet | J35: 560 | K35: =K34+H35-J35 -> 850 | L35: =L34+F35+G35-H35 -> 16075.07
C36: 28.02.23 | D36: Archna returned support | F36: 2600 | I36: Spirirual camp | J36: 180 | K36: =K35+H36-J36 -> 670 | L36: =L35+F36+G36-H36 -> 18675.07
C37: 03.03.23 | H37: 17000 | K37: =K36+H37-J37 -> 17670 | L37: =L36+F37+G37-H37 -> 1675.07
C38: 05.03.23 | I38: DR | J38: 7800 | K38: =K37+H38-J38 -> 9870 | L38: =L37+F38+G38-H38 -> 1675.07
C39: 05.03.23 | I39: DR | J39: 4000 | K39: =K38+H39-J39 -> 5870 | L39: =L38+F39+G39-H39 -> 1675.07
C40: 05.03.23 | I40: Office assistance | J40: 1300 | K40: =K39+H40-J40 -> 4570 | L40: =L39+F40+G40-H40 -> 1675.07
C41: 06.03.23 | I41: Website development | J41: 2000 | K41: =K40+H41-J41 -> 2570 | L41: =L40+F41+G41-H41 -> 1675.07
C42: 12.03.23 | H42: 649 | K42: 2570 | L42: =L41+F42+G42-H42 -> 1026.07
...

Sheet 23-24
D5: Date | F5: Cash | G5: Through Bank | H5: Deposited in Bank | I5: Withdrawn from Bank | J5: Expenditure | L5: Balance
J6: Purpose | K6: Amount | L6: Cash in hand | M6: Cash in Bank
J7: B/F | L7: ='22-23'!K43 -> 2570 | M7: ='22-23'!L43 -> 4026.07
D8: 2.4.23 | E8: K.C. Tripathi | F8: 1000 | J8: Meeting with Bord of Directors | K8: 2170 | L8: =L7+F8-K8 -> 1400 | M8: 4026.07
D9: 22.4.23 | J9: Eqarth Day | K9: 980 | L9: =L8+F9-K9 -> 420 | M9: 4026.07
D10: 25.4.23 | E10: Atul Verma | F10: 1100 | J10: Panchaayt Diwas | K10: 1230 | L10: =L9+F10-K10 -> 290 | M10: 4026.07
D11: 31.5.23 | I11: 590 | J11: Account keeping charges | L11: 290 | M11: =M10-I11 -> 3436.07
D12: 30.6.23 | I12: 590 | J12: Account keeping charges | L12: 290 | M12: =M11+H12-I12 -> 2846.07
D13: 31.7.23 | I13: 590 | J13: Account keeping charges | L13: 290 | M13: =M12+H13-I13 -> 2256.07
D14: 18.8.23 | E14: RD | F14: 10000 | H14: 10000 | L14: 290 | M14: =M13+H14-I14 -> 12256.07
D15: 29.8.23 | H15: 0 | I15: 5000 | J15: DR | K15: 5000 | L15: 290 | M15: =M14+H15-I15 -> 7256.07
D16: 13.9.23 | H16: 30 | L16: 290 | M16: =M15+H16-I16 -> 7286.07
D17: 19.9.23 | H17: 370 | L17: 290 | M17: =M16+H17-I17 -> 7656.07
D18: 25.9.23 | E18: K.C. Tripathi | F18: 1000 | J18: Ban Uncle Day | K18: 760 | L18: =L17+F18-K18 -> 530 | M18: =M17+H18-I18 -> 7656.07
D19: 27.9.23 | I19: 5000 | J19: DR | K19: 5000 | L19: 530 | M19: =M18+H19-I19 -> 2656.07
D20: 31.10.23 | I20: 590 | J20: Account keeping charges | L20: 530 | M20: =M19+H20-I20 -> 2066.07
D21: 30.11.23 | I21: 590 | J21: Account keeping charges | L21: 530 | M21: =M20+H21-I21 -> 1476.07
D22: 3.12.23 | J22: Development Car Day | K22: 180 | L22: =L21-K22 -> 350 | M22: =M21+H22-I22 -> 1476.07
D23: 31.12.23 | I23: 590 | J23: Account keeping charges | L23: 350 | M23: =M22+H23-I23 -> 886.07
D24: 2.1.24 | E24: K.C. Tripathi | F24: 500 | G24: =SUM(F24) -> 500 | J24: Bord meeting | K24: 770 | L24: =L23+F24-K24 -> 80 | M24: =M23+H24-I24 -> 886.07
D25: 5.1.24 | E25: Poonam RD | G25: 10000 | H25: 10000 | L25: 80 | M25: =M24+H25-I25 -> 10886.07
D26: 18.1.24 | E26: Poonam DR | I26: 10000 | J26: DR | K26: 10000 | L26: 80 | M26: =M25+H26-I26 -> 886.07
D27: 31.1.24 | E27: Neera Tripathi | F27: 1000 | J27: Foundation Day | K27: 610 | L27: =L26+F27-K27 -> 470 | M27: =M26+H27-I27 -> 886.07
D28: 29.2.24 | I28: 590 | J28: Account keeping charges | L28: 470 | M28: =M27+H28-I28 -> 296.07
D29: 12.3.24 | I29: 296.07 | J29: Account keeping charges | L29: 470 | M29: =M28+H29-I29 -> 0

Sheet 24-25
C3: Statement of account period - 1st April 2022 till 31st March 2026
C4: Date | E4: Cash | F4: Through Bank | G4: Deposited in Bank | H4: Withdrawn from Bank | I4: Expenditure | K4: Balance
I5: Purpose | J5: Amount | K5: Cash in hand | L5: Cash in Bank
I6: B/F | K6: ='23-24'!L29 -> 470 | L6: ='[1]23-24'!L26 -> 0
C7: 2.4.24 | D7: Atul Verma | E7: 1100 | I7: Bord meeting | J7: 780 | K7: =K6+E7-J7 -> 790
C8: 22.4.24 | D8: Neera Tripathi | E8: 500 | I8: Earth Day | J8: 870 | K8: =K7+E8-J8 -> 420
C9: 25.4.24 | D9: K. C. Tripathi | E9: 1000 | I9: Panchayat Diwas | J9: 1120 | K9: =K8+E9-J9 -> 300
C10: 5.5.24 | D10: SSS | F10: =G10 -> 5 | G10: 5 | K10: 300 | L10: 5
C11: 5.5.24 | D11: SSS | F11: =G11 -> 20000 | G11: 20000 | K11: 300 | L11: =L10+G11-H11 -> 20005
C12: 5.5.24 | G12: 0 | H12: 352.93 | I12: Account keeping charges | K12: 300 | L12: =L11+G12-H12 -> 19652.07
C13: 6.5.24 | G13: 0 | H13: 1180 | I13: Account keeping charges | K13: 300 | L13: =L12+G13-H13 -> 18472.07
C14: 21.5.24 | G14: 0 | H14: 5000 | I14: Spiritual camps | J14: 970 | K14: =K13+H14-J14 -> 4330 | L14: =L13+G14-H14 -> 13472.07
C15: 26.5.24 | I15: Community meet | J15: 1120 | K15: =K14+H15-J15 -> 3210
C16: 29.5.24 | I16: Community meet | J16: 1210 | K16: =K15+H16-J16 -> 2000
C17: 5.6.24 | I17: Community meet | J17: 1130 | K17: =K16+H17-J17 -> 870
C18: 18.6.24 | I18: Community meet | J18: 760 | K18: =K17+H18-J18 -> 110
C19: 27.6.24 | G19: 0 | H19: 3000 | I19: Experience sharing meet | J19: 1760 | K19: =K18+H19-J19 -> 1350 | L19: =L14+G19-H19 -> 10472.07
I20: Community meet | J20: 970 | K20: =K19+H20-J20 -> 380
C21: 25.9.24 | D21: Gaurav Pandey | E21: 1000 | I21: Ban Uncle Day | J21: 540 | K21: =K20+H21-J21+E21 -> 840
C22: 3.12.24 | I22: Development Car Day | J22: 570 | K22: =K21+H22-J22 -> 270
C23: 27.12.24 | G23: 0 | H23: 9000 | I23: Workshop to develop action plan | J23: 3660 | K23: =K22+H23-J23 -> 5610 | L23: =L19+G23-H23 -> 1472.07
C24: 29.12.24 | I24: Development of educational material | J24: 2980 | K24: =K23+H24-J24 -> 2630
C25: 30.12.24 | I25: Meeting of Bord Directors | J25: 1480 | K25: =K24+H25-J25 -> 1150
C26: 5.1.25 | I26: Formulation of project | J26: 760 | K26: =K25+H26-J26 -> 390
C27: 31.1.25 | I27: Foundation Day | J27: 270 | K27: =K26+H27-J27 -> 120
C28: 31.1.25 | G28: 0 | H28: 590 | I28: Account keeping charges | K28: 120 | L28: =L23+G28-H28 -> 882.07
C29: 28.2.25 | G29: 0 | H29: 590 | I29: Account keeping charges | K29: 120 | L29: =L28+G29-H29 -> 292.07
C30: 12.3.25 | G30: 0 | H30: 292.07 | I30: Account keeping charges | K30: 120 | L30: =L29+G30-H30 -> 0

Sheet 25-26
D5: Statement of account period - 1st April 2022 till 31st March 2026
D6: Date | F6: Cash | G6: Through Bank | H6: Deposited in Bank | I6: Withdrawn from Bank | J6: Expenditure | L6: Balance
J7: Purpose | K7: Amount | L7: Cash in hand | M7: Cash in Bank
L8: ='24-25'!K30 -> 120 | M8: ='[1]24-25'!L32 -> 0
D9: 22.4.25 | E9: Pranshu Tripathi | F9: 1000 | J9: Earth Day | K9: 380 | L9: =L8+F9-K9 -> 740 | M9: 0
D10: 25.4.25 | E10: K. C. Tripathi | F10: 1100 | J10: Panchayat Dawas | K10: 1270 | L10: =L9+F10-K10 -> 570 | M10: 0
D11: 25.9.25 | J11: Bank Uncle Day | K11: 210 | L11: =L10+F11-K11 -> 360 | M11: 0
D12: 3.12.25 | E12: Neera Tripathi | F12: 1000 | J12: Development Car Day | K12: 370 | L12: =L11+F12-K12 -> 990 | M12: 0
D13: 31.1.26 | J13: Foundaton Day | K13: 280 | L13: =L12+F13-K13 -> 710 | M13: 0
D14: 2.2.26 | J14: Directors meet | K14: 190 | L14: =L13+F14-K14 -> 520 | M14: 0
D15: 15.3.26 | E15: Neera RD | F15: 6000 | L15: 6520 | M15: 0
D16: 16.3.26 | J16: Honorarium of experts | K16: 5000 | L16: 1520
D17: 23.3.26 | E17: Jajeevan mission report | H17: 10000 | L17: 1520 | M17: 10000
D18: 23.3.26 | I18: 653 | J18: Bank charges | L18: 1520 | M18: =M17+H18-I18 -> 9347
D19: 24.3.26 | I19: 7080 | J19: Bank charges | L19: 1520 | M19: =M18+H19-I19 -> 2267
D20: 31.3.26 | I20: 590 | J20: Bank charges | L20: 1520 | M20: =M19+H20-I20 -> 1677

Sheet 26-27
D9: Statement of account period - 1st April 2022 till 31st March 2026
D10: Date | F10: Cash | G10: Through Bank | H10: Deposited in Bank | I10: Withdrawn from Bank | J10: Expenditure | L10: Balance
J11: Purpose | K11: Amount | L11: Cash in hand | M11: Cash in Bank
D12: B/F | L12: ='25-26'!L20 -> 1520 | M12: ='25-26'!M20 -> 1677
D13: 3.4.26 | F13: 1000 | J13: Directors meet | K13: 1110 | L13: =L12+F13-K13 -> 1410 | M13: =M12+H13 -> 1677
D14: 3.4.26 | F14: 4000 | L14: 5410 | M14: 1677
D15: 3.4.26 | F15: 4000 | L15: =L14+F14 -> 9410 | M15: 1677
D16: 3.4.26 | F16: 4000 | L16: =L15+F15 -> 13410 | M16: 1677
D17: 3.4.26 | E17: RD | F17: 1000 | L17: =L16+F16 -> 17410 | M17: 1677
D18: 4.4.26 | E18: RD | F18: 4000 | L18: =L17+F17 -> 18410 | M18: 1677
D19: 4.4.26 | E19: RD | F19: 5000 | L19: =L18+F18 -> 22410 | M19: 1677
D20: 5.4.26 | E20: RD | F20: 3000 | L20: =L19+F19 -> 27410 | M20: 1677
D21: 6.4.26 | H21: 25000 | L21: =L20-H21 -> 2410 | M21: =M13+H21 -> 26677
D22: 22.4.26 | J22: Earth Day | K22: 310 | L22: =L21-K22 -> 2100
D23: 24.4.26 | J23: Panchayat Diwas | K23: 1160 | L23: =L22-K23 -> 940
D24: 10.5.26 | F24: 1000 | L24: 1940
D25: 11.5.26 | G25: =H25 -> 95.95 | H25: 95.95 | L25: 1940 | M25: =M21+H25 -> 26772.95
D26: 12.5.26 | G26: =H26 -> 95.95 | H26: 95.95 | L26: 1940 | M26: =M25+H26 -> 26868.9
D27: 28.5.26 | E27: RD | G27: =H27 -> 6000 | H27: 6000 | J27: Website | K27: 1000 | L27: 940 | M27: =M26+H27 -> 32868.9

Sheet State of account
F2: Financial position of AIRD
F3: Date | G3: Received | H3: cash in hand | I3: Bank deposit | J3: Expenditure | K3: Returnable donation | L3: Donation returned | M3: laibality
F4: 3.12.2019 | G4: 1100 | H4: 1100 | I4: 0 | J4: 0 | M4: 0
F5: 3.3.2020 | G5: 11800 | H5: 140 | I5: 0 | J5: 11660 | M5: 0
F6: 3.12.2021 | G6: 14285 | H6: 460 | I6: 11143 | J6: 2821 | K6: 11000 | M6: 11000
F7: 31.3.2022 | G7: 14200 | H7: 1350 | I7: 16494 | J7: 7959 | K7: 5000 | L7: 5000 | M7: 11000
F8: 18.3.2023 | G8: 57681 | H8: 2570 | I8: 4026 | J8: 69160 | K8: 33800 | L8: 38800 | M8: 6000
F9: 12.3.2024 | G9: 25100 | H9: 470 | I9: 0 | J9: 26700 | K9: 20000 | L9: 20000 | M9: 6000
F10: 12.3.2025 | G10: 23605 | H10: 120 | I10: 0 | J10: 20950 | K10: 0 | L10: 0 | M10: 6000
F11: 31.3.2026 | G11: 9100 | H11: 1520 | I11: 1677 | J11: 7700 | K11: 10000 | L11: 0 | M11: 16000
